Workbook

Sheet Start Here
A1: Colosseum knowledge pack — Legion Capital
A2: Everything the app needs to run and be tested. Data, documents and this workbook are generated from one source, so they always agree.
A4: Company | B4: Legion Capital Ltd: a fictional RBI-registered NBFC (digital personal and SME loans) with a merchant checkout product, Legion Pay. About 10 million payment transactions (≈ ₹1,500 crore) a month, all through Arvanta Payments today.
A5: Decision | B5: Should Legion Capital move 40% of its payment volume (about ₹600 crore a month) from Arvanta Payments to Brevis Pay?
A7: Tab | B7: What it is and where the app uses it
A8: Numbers | B8: Inputs and formulas behind the planted numbers, for the full 40% move and a 15% first phase. Lets you sanity-check what Finance should calculate.
A9: Planted Facts | B9: 71 facts the demo depends on: 10+ per adviser. Loaded into BigQuery colosseum.facts. The Expected conclusion, Direction, Impact and Blocking columns are the ANSWER KEY: they live only in colosseum_eval and are never shown to agents.
A10: Background Facts | B10: 54 everyday company facts unrelated to this decision. They make the fact store realistic and test that routing and retrieval stay focused as facts grow.
A11: Advisers | B11: The adviser registry (config/advisers.yaml): lens, capability statements the harness embeds for routing, criteria each adviser scores, and who can block.
A12: Routing Tests | B12: 8 decision briefs with the advisers the harness must and must not pick. Used on Day 5.
A13: Moderator Tests | B13: 14 cases: claims the moderator must keep, flag or strike, and memos it must pass, mark incomplete or mark wrong. Used on Day 7.
A14: Expected Outcome | B14: What a good Colosseum run should recommend for the demo decision.
A15: Tracker | B15: Day 1 done + Days 2–11 with milestones and minutes.
A17: Note | B17: Keep using the Setup tab in your Day 1 workbook for project IDs and model IDs.
... A19: Fictional | B19: Legion Capital, Arvanta Payments, Brevis Pay, Sentrix Risk, Vireo Finance, Coral Bank and Tamra Bank are all fictional.

Sheet Numbers
A1: Planted numbers and the calculations Finance should reproduce
A2: Blue = input · Black = formula. Columns B and C compare the full 40% move with a 15% first phase.
A4: Inputs
A5: Monthly payment volume | B5: 1500 | C5: ₹ crore
A6: Share moved — full plan | B6: 0.4 | C6: %
A7: Share moved — phase 1 | B7: 0.15 | C7: %
A8: Arvanta blended fee | B8: 0.002 | C8: % of volume
A9: Brevis blended fee (final quote) | B9: 0.00176 | C9: % of volume
A10: Brevis India-only hosting add-on (flat) | B10: 6 | C10: ₹ lakh / month
A11: Funding-cost benefit at 40% (T+1 settlement) | B11: 4 | C11: ₹ lakh / month
A12: Disputes per month at 40% | B12: 2000 | C12: disputes
A13: Arvanta dispute fee | B13: 150 | C13: ₹ per dispute
A14: Brevis dispute fee | B14: 250 | C14: ₹ per dispute
A15: One-time migration cost | B15: 40 | C15: ₹ lakh
A16: Arvanta early-exit fee | B16: 25 | C16: ₹ lakh
... A23: Cost per support ticket | B23: 180 | C23: ₹
A26: Scenario comparison | B26: Full move (40%) | C26: Phase 1 (15%) | D26: Unit
A27: Share moved | B27: =$B$6 -> 0.4 | C27: =$B$7 -> 0.15 | D27: %
A28: Volume moved | B28: =$B$5*B27 -> 600 | C28: =$B$5*C27 -> 225 | D28: ₹ crore / month
A29: Cost on Arvanta | B29: =B28*100*$B$8 -> 120 | C29: =C28*100*$B$8 -> 45 | D29: ₹ lakh / month
A30: Cost on Brevis | B30: =B28*100*$B$9 -> 105.6 | C30: =C28*100*$B$9 -> 39.6 | D30: ₹ lakh / month
A31: Gross fee saving | B31: =B29-B30 -> 14.4 | C31: =C29-C30 -> 5.4 | D31: ₹ lakh / month
A32: Funding-cost benefit | B32: =$B$11*B27/$B$6 -> 4 | C32: =$B$11*C27/$B$6 -> 1.5 | D32: ₹ lakh / month
A33: Extra dispute cost on Brevis | B33: =$B$12*(B27/$B$6)*($B$14-$B$13)/100000 -> 2 | C33: =$B$12*(C27/$B$6)*($B$14-$B$13)/100000 -> 0.75 | D33: ₹ lakh / month
A34: India-only hosting add-on (flat) | B34: =$B$10 -> 6 | C34: =$B$10 -> 6 | D34: ₹ lakh / month
A35: Net monthly benefit (costs only) | B35: =B31+B32-B33-B34 -> 10.4 | C35: =C31+C32-C33-C34 -> 0.15 | D35: ₹ lakh / month
A36: Arvanta share after the move | B36: =1-B27 -> 0.6 | C36: =1-C27 -> 0.85 | D36: %
A37: Exit fee triggered? | B37: =IF(B36<$B$17,"Yes","No") -> Yes | C37: =IF(C36<$B$17,"Yes","No") -> No
A38: One-time cost | B38: =$B$15+IF(B37="Yes",$B$16,0) -> 65 | C38: =$B$15+IF(C37="Yes",$B$16,0) -> 40 | D38: ₹ lakh
A39: Payback (costs only) | B39: =IF(B35>0,B38/B35,"No payback") -> 6.25 | C39: =IF(C35>0,C38/C35,"No payback") -> 266.66667 | D39: months
A40: Cross-border revenue unlocked | B40: =$B$19*$B$20*100 -> 9 | C40: =$B$19*$B$20*100 -> 9 | D40: ₹ lakh / month
A41: Net monthly benefit incl. cross-border | B41: =B35+B40 -> 19.4 | C41: =C35+C40 -> 9.15 | D41: ₹ lakh / month
A42: Payback incl. cross-border | B42: =IF(B41>0,B38/B41,"No payback") -> 3.3505155 | C42: =IF(C41>0,C38/C41,"No payback") -> 4.3715847 | D42: months
A43: Meets the 70% OKR? | B43: =IF(B36<=$B$18,"Yes","No") -> Yes | C43: =IF(C36<=$B$18,"Yes","No") -> No
A45: Other checks
A46: Cross-border fee revenue per year | B46: =$B$19*$B$20*12*100 -> 108 | D46: ₹ lakh / year (≈ ₹1.08 crore)
A47: Settlement complaint growth, July → September | B47: =IFERROR($B$22/$B$21-1,0) -> 1.8333333 | D47: %
A48: Cost of September settlement tickets | B48: =$B$22*$B$23 -> 61200 | D48: ₹
A50: Reading it: the full 40% move pays back its one-time costs in about 6 months on costs alone. Phase 1 alone barely breaks even because the ₹6 lakh add-on is flat, but it avoids the exit fee and unlocks cross-border revenue. That tension is what the debate should surface.

Sheet Planted Facts
A1: Planted facts — 71 facts, 10+ per adviser
A2: Columns A–J are what the app's fact store holds. Columns K–N are the ANSWER KEY (kept in colosseum_eval, never shown to agents).
A3: Fact ID | B3: Adviser | C3: Topic | D3: Fact | E3: Value | F3: Unit | G3: As of | H3: Source | I3: Reliability | J3: Superseded by | K3: Expected conclusion | L3: Direction | M3: Impact | N3: Blocking
A4: FIN-01 | B4: Finance | C4: volume | D4: Legion Capital processed 10.0 million payment transactions worth about ₹1,500 crore in September 2026 (average ₹1,500). | E4: 1500 | F4: INR crore / month | G4: 2026-09-30 | H4: transactions_monthly | I4: high | K4: 40% of volume is about ₹600 crore a month, the slice being decided on. | L4: neutral | M4: high
A5: FIN-02 | B5: Finance | C5: fees | D5: Arvanta Payments charges a blended fee of 0.20% of payment volume. | E5: 0.2 | F5: % of volume | G5: 2023-04-01 | H5: Arvanta_MSA_Excerpt.pdf §4.1 | I5: high | K5: Cost of the 40% slice on Arvanta is ₹120 lakh a month. | L5: neutral | M5: high
A6: FIN-03 | B6: Finance | C6: fees | D6: Brevis Pay's final quote (15 Sep 2026) is a blended fee of 0.176% of volume, 12% below Arvanta. | E6: 0.176 | F6: % of volume | G6: 2026-09-15 | H6: Brevis_Draft_Agreement.pdf Schedule 1 | I6: high | K6: Gross saving on the 40% slice is ₹14.4 lakh a month (12%). | L6: favours B | M6: high
A7: FIN-04 | B7: Finance | C7: fees | D7: Brevis Pay's India-only hosting add-on, needed to keep fraud scoring in India, costs a flat ₹6 lakh a month. | E7: 6 | F7: INR lakh / month | G7: 2026-09-15 | H7: Brevis_Draft_Agreement.pdf Schedule 1 item 4 | I7: high | K7: Fixing the InfoSec block costs ₹6 lakh a month; because it is flat, it eats most of the saving in a small first phase. | L7: caution | M7: high
A8: FIN-05 | B8: Finance | C8: one_time_cost | D8: The one-time cost of migrating to Brevis Pay (engineering, certification, testing) is estimated at ₹40 lakh. | E8: 40 | F8: INR lakh one-time | G8: 2026-09-25 | H8: Ops_Review_Q3_2026.pdf §5 | I8: medium | K8: Add ₹40 lakh migration cost (plus the ₹25 lakh exit fee if triggered) to payback. | L8: caution | M8: medium
A9: FIN-06 | B9: Finance | C9: treasury | D9: Treasury estimates that Brevis Pay's T+1 card settlement (vs Arvanta's T+2) would cut funding cost by about ₹4 lakh a month on the 40% slice. | E9: 4 | F9: INR lakh / month | G9: 2026-09-24 | H9: Board_Minutes_Sep2026.pdf item 3 | I9: medium | K9: Adds ₹4 lakh a month of benefit on the 40% slice. | L9: favours B | M9: medium
A10: FIN-07 | B10: Finance | C10: treasury | D10: Legion Capital's cost of funds is 9.5% a year. | E10: 9.5 | F10: % per year | G10: 2026-09-24 | H10: Board_Minutes_Sep2026.pdf item 3 | I10: high | K10: Context for valuing faster settlement. | L10: neutral | M10: low
A11: FIN-08 | B11: Finance | C11: fees | D11: Dispute handling fees: Arvanta ₹150 and Brevis ₹250 per dispute. About 2,000 disputes a month arise on the 40% slice. | E11: 2 | F11: INR lakh / month | G11: 2026-09-15 | H11: Brevis_Draft_Agreement.pdf Schedule 1 item 2; Arvanta_MSA_Excerpt.pdf §4.3; Ops_Review_Q3_2026.pdf §1 | I11: high | K11: Brevis costs ₹2 lakh a month more in dispute fees on the 40% slice. | L11: favours A | M11: medium
A12: FIN-09 | B12: Finance | C12: budget | D12: FY27 payments-cost budget is ₹33 crore; the current run-rate is ₹36 crore a year (9% over budget). | E12: 36 | F12: INR crore / year | G12: 2026-09-24 | H12: Board_Minutes_Sep2026.pdf item 2 | I12: high | K12: There is real pressure to cut payment costs. | L12: favours B | M12: medium
A13: FIN-10 | B13: Finance | C13: forecast | D13: Payment volume is forecast to grow 25% over the next 12 months. | E13: 25 | F13: % next 12 months | G13: 2026-07-01 | H13: Legion_Strategy_OKRs_FY27.pdf §2 | I13: medium | K13: Savings and fees scale with volume, so the gap grows over time. | L13: favours B | M13: low
A14: FIN-11 | B14: Finance | C14: targets | D14: The board's FY27 target is to cut the cost-to-income ratio from 48% to 42%. | E14: 42 | F14: % | G14: 2026-09-24 | H14: Board_Minutes_Sep2026.pdf item 2 | I14: high | K14: Supports cost reduction, but not at the expense of a compliance breach. | L14: favours B | M14: medium
A15: FIN-12 | B15: Finance | C15: fees | D15: An early internal email (March 2026) estimated that Brevis would be 18% cheaper than Arvanta. | E15: 18 | F15: % | G15: 2026-03-12 | H15: Finance_Email_Mar2026.pdf | I15: low | J15: FIN-03 | K15: Out of date. Superseded by the final quote (FIN-03, 12%). Must not be used. | L15: neutral | M15: low
A16: BUS-01 | B16: Business | C16: pipeline | D16: 30 cross-border SME merchants in the sales pipeline, worth about ₹45 crore a month, need international card acceptance, which only Brevis Pay supports. | E16: 45 | F16: INR crore / month | G16: 2026-09-30 | H16: sales_pipeline | I16: high | K16: Moving to Brevis unlocks a ₹45 crore/month pipeline. | L16: favours B | M16: high
A17: BUS-02 | B17: Business | C17: okr | D17: FY27 OKR: no single payment gateway should carry more than 70% of volume by 31 March 2027. | E17: 70 | F17: % | G17: 2026-04-01 | H17: Legion_Strategy_OKRs_FY27.pdf §3 OKR 2.1 | I17: high | K17: At least 30% must move by 31 Mar 2027; a 15% phase alone doesn't meet it. | L17: favours B | M17: high
A18: BUS-03 | B18: Business | C18: market | D18: Competitor Vireo Finance moved to a multi-gateway setup in June 2026 and now advertises '99.9% payment uptime' to SME merchants. | E18: multi-gateway since Jun 2026 | G18: 2026-07-15 | H18: Legion_Strategy_OKRs_FY27.pdf §5 | I18: medium | K18: Competitive pressure to reduce single-gateway dependence. | L18: favours B | M18: medium
A19: BUS-04 | B19: Business | C19: product | D19: Legion Pay Later (BNPL at checkout) is planned for Q1 FY28 (Apr–Jun 2027). Brevis Pay has native EMI/BNPL APIs; Arvanta would need a 4-month custom build. | E19: 4 | F19: months | G19: 2026-07-15 | H19: Legion_Strategy_OKRs_FY27.pdf §4 | I19: medium | K19: Brevis shortens time-to-market for BNPL. | L19: favours B | M19: medium
A20: BUS-05 | B20: Business | C20: vendor_offer | D20: Arvanta has offered an 8% fee cut if Legion commits 100% of volume for 3 more years. | E20: 8 | F20: % | G20: 2026-09-24 | H20: Board_Minutes_Sep2026.pdf item 4 | I20: high | K20: Real alternative, but it conflicts with the 70% vendor OKR and locks out cross-border. | L20: favours A | M20: medium
A21: BUS-06 | B21: Business | C21: revenue | D21: Expected fee revenue from the cross-border pipeline is about ₹1.08 crore a year (0.2% take rate on ₹45 crore a month). | E21: 1.08 | F21: INR crore / year | G21: 2026-09-30 | H21: Legion_Strategy_OKRs_FY27.pdf §4 | I21: medium | K21: About ₹9 lakh a month of new revenue, larger than the fee saving in phase 1. | L21: favours B | M21: high
A22: BUS-07 | B22: Business | C22: partners | D22: Two of Legion's top five co-lending partners already settle through Brevis Pay. | E22: 2 | F22: partners | G22: 2026-07-15 | H22: Legion_Strategy_OKRs_FY27.pdf §5 | I22: medium | K22: Simpler reconciliation with key partners. | L22: favours B | M22: low
A23: BUS-08 | B23: Business | C23: sales | D23: In Q2–Q3 FY27, 70% of lost SME deals cited lack of international card acceptance. | E23: 70 | F23: % | G23: 2026-09-30 | H23: Legion_Strategy_OKRs_FY27.pdf §5 | I23: medium | K23: International acceptance is a real sales blocker. | L23: favours B | M23: medium
A24: BUS-09 | B24: Business | C24: timeline | D24: The board wants cross-border card acceptance live by 31 March 2027. | E24: 2027-03-31 | F24: date | G24: 2026-09-24 | H24: Board_Minutes_Sep2026.pdf item 5 | I24: high | K24: Time pressure: a phased plan must still reach cross-border by end of March. | L24: favours B | M24: medium
A25: BUS-10 | B25: Business | C25: concentration_risk | D25: Arvanta's 14 June 2026 outage delayed ₹2.3 crore of loan collections; ₹11 lakh of wrongly charged late fees had to be waived for 1,900 borrowers. | E25: 2.3 | F25: INR crore | G25: 2026-06-14 | H25: Board_Minutes_Sep2026.pdf item 6 | I25: high | K25: Shows the cost of depending on one gateway. | L25: favours B | M25: medium
A26: BUS-11 | B26: Business | C26: vendor_maturity | D26: Brevis Pay is 3 years old with about 1,200 merchants; Arvanta is 9 years old with about 40,000 merchants. | E26: 1200 | F26: merchants | G26: 2026-07-15 | H26: Legion_Strategy_OKRs_FY27.pdf §5 | I26: medium | K26: Vendor maturity risk argues for a phased, reversible move. | L26: caution | M26: medium
A27: CUS-01 | B27: Customer | C27: complaints | D27: Settlement-delay complaints about Arvanta rose from 120 (July) to 210 (August) to 340 (September 2026). | E27: 340 | F27: tickets / month | G27: 2026-09-30 | H27: support_tickets_monthly | I27: high | K27: Complaints nearly tripled in 3 months; staying 100% on Arvanta has a customer cost. | L27: favours B | M27: high
A28: CUS-02 | B28: Customer | C28: churn_risk | D28: Four large merchants (M-104, M-221, M-307, M-412), together about ₹38 crore a month, have threatened to leave over settlement delays. | E28: 38 | F28: INR crore / month | G28: 2026-09-30 | H28: Customer_Insights_Q3_2026.pdf §2 | I28: high | K28: Urgent revenue risk if settlement delays continue. | L28: favours B | M28: high
A29: CUS-03 | B29: Customer | C29: complaints | D29: About 900 failed EMI auto-debit complaints arrive each month; in 14% of them the borrower was wrongly charged a late fee. | E29: 900 | F29: tickets / month | G29: 2026-09-30 | H29: support_tickets_monthly | I29: high | K29: Payment failures hurt borrowers directly; mandate success rate matters. | L29: neutral | M29: medium
A30: CUS-04 | B30: Customer | C30: conversion | D30: In the Brevis pilot (2% of traffic, Aug–Sep 2026), mobile checkout conversion was 3.1 points higher than on Arvanta. | E30: 3.1 | F30: percentage points | G30: 2026-09-30 | H30: Customer_Insights_Q3_2026.pdf §3 | I30: medium | K30: Better mobile conversion on Brevis (mobile only; pilot sample). | L30: favours B | M30: medium
A31: CUS-05 | B31: Customer | C31: complaints | D31: During the pilot, complaints from Coral Bank and Tamra Bank customers were 40% higher on Brevis than on Arvanta. | E31: 40 | F31: % | G31: 2026-09-30 | H31: Customer_Insights_Q3_2026.pdf §3 | I31: medium | K31: Keep Coral Bank and Tamra Bank traffic on Arvanta. | L31: caution | M31: medium
A32: CUS-06 | B32: Customer | C32: satisfaction | D32: Legion's merchant NPS is 41 against an industry benchmark of 50. | E32: 41 | F32: score | G32: 2026-09-30 | H32: Customer_Insights_Q3_2026.pdf §1 | I32: medium | K32: Merchant experience needs improving. | L32: neutral | M32: low
A33: CUS-07 | B33: Customer | C33: refunds | D33: Average refund turnaround is 5.2 days on Arvanta and 3.0 days on Brevis (pilot). | E33: 3 | F33: days | G33: 2026-09-30 | H33: Customer_Insights_Q3_2026.pdf §3 | I33: medium | K33: Faster refunds on Brevis. | L33: favours B | M33: low
A34: CUS-08 | B34: Customer | C34: accessibility | D34: Brevis checkout supports 11 Indian languages; Arvanta supports 4. | E34: 11 | F34: languages | G34: 2026-09-30 | H34: Customer_Insights_Q3_2026.pdf §4 | I34: medium | K34: Better reach for non-English-first customers. | L34: favours B | M34: low
A35: CUS-09 | B35: Customer | C35: churn | D35: Monthly merchant churn was 2.1% in September 2026, up from 1.4% in Q1 FY27. | E35: 2.1 | F35: % per month | G35: 2026-09-30 | H35: Customer_Insights_Q3_2026.pdf §2 | I35: high | K35: Churn is rising; settlement experience is a likely driver. | L35: favours B | M35: medium
A36: CUS-10 | B36: Customer | C36: grievance | D36: 20 of 340 settlement complaints in September (about 6%) breached the 30-day grievance-resolution limit. | E36: 20 | F36: tickets | G36: 2026-09-30 | H36: support_tickets_monthly | I36: high | K36: Regulatory risk from slow complaint resolution; adds urgency. | L36: caution | M36: medium
... A41: LEG-03 | B41: Legal | C41: renewal | D41: Arvanta MSA renews automatically for 2 years unless notice is given 6 months before 31 March 2028. | E41: 2 | F41: years | G41: 2023-04-01 | H41: Arvanta_MSA_Excerpt.pdf §2 | I41: high | K41: Calendar item; not decisive now. | L41: neutral | M41: low
A42: LEG-04 | B42: Legal | C42: data_location | D42: The Brevis draft agreement has no clause on where data is stored or processed. | E42: missing | G42: 2026-09-15 | H42: Brevis_Draft_Agreement.pdf §7 | I42: high | K42: Must add an India-only storage and processing clause before signing. | L42: caution | M42: high
A43: LEG-05 | B43: Legal | C43: liability | D43: Brevis draft caps liability at 3 months' fees; Arvanta's cap is 12 months' fees. | E43: 3 | F43: months of fees | G43: 2026-09-15 | H43: Brevis_Draft_Agreement.pdf §9; Arvanta_MSA_Excerpt.pdf §8.1 | I43: high | K43: Weaker protection with Brevis; negotiate a higher cap. | L43: favours A | M43: medium
A44: LEG-06 | B44: Legal | C44: pricing_terms | D44: Brevis draft lets Brevis change prices with 30 days' notice. | E44: 30 | F44: days | G44: 2026-09-15 | H44: Brevis_Draft_Agreement.pdf Schedule 1 note | I44: high | K44: Savings aren't secure; negotiate a 24-month price lock. | L44: caution | M44: medium
...

Sheet Background Facts
A1: Background facts — 54 everyday company facts
A2: Unrelated to the gateway decision. They test that routing and retrieval stay focused as the fact store grows.
A3: Fact ID | B3: Adviser domain | C3: Topic | D3: Fact | E3: Value | F3: Unit
A4: FIN-101 | B4: Finance | C4: loan_book | D4: Legion Capital's loan book stands at ₹8,400 crore. | E4: 8400 | F4: INR crore
A5: FIN-102 | B5: Finance | C5: asset_quality | D5: Gross NPA ratio is 2.9%. | E5: 2.9 | F5: %
A6: FIN-103 | B6: Finance | C6: margins | D6: Net interest margin is 9.1%. | E6: 9.1 | F6: %
A7: FIN-104 | B7: Finance | C7: capital | D7: Capital adequacy ratio is 24%. | E7: 24 | F7: %
A8: FIN-105 | B8: Finance | C8: marketing | D8: Marketing spend is ₹6 crore a month. | E8: 6 | F8: INR crore / month
A9: FIN-106 | B9: Finance | C9: facilities | D9: The Pune office lease costs ₹45 lakh a year. | E9: 45 | F9: INR lakh / year
A10: FIN-107 | B10: Finance | C10: borrowing | D10: 62% of borrowings are bank term loans; 38% are NCDs. | E10: 62 | F10: %
A11: FIN-108 | B11: Finance | C11: tax | D11: Effective tax rate is 25.2%. | E11: 25.2 | F11: %
A12: FIN-109 | B12: Finance | C12: collections | D12: Collection efficiency was 98.4% in September 2026. | E12: 98.4 | F12: %
A13: BUS-101 | B13: Business | C13: growth | D13: The app averages 1.2 million downloads a month. | E13: 1.2 | F13: million / month
A14: BUS-102 | B14: Business | C14: lending | D14: The average personal loan ticket is ₹85,000. | E14: 85000 | F14: INR
A15: BUS-103 | B15: Business | C15: partnerships | D15: Legion has embedded-finance partnerships with 3 two-wheeler makers. | E15: 3 | F15: partners
... A18: BUS-106 | B18: Business | C18: expansion | D18: Legion plans to enter 12 new cities in FY28. | E18: 12 | F18: cities
A19: BUS-107 | B19: Business | C19: product | D19: Credit-line product launch is planned for Q2 FY28. | E19: Q2 FY28
A20: BUS-108 | B20: Business | C20: sales | D20: The SME sales team has 140 people. | E20: 140 | F20: people
A21: BUS-109 | B21: Business | C21: partnerships | D21: Co-lending book is ₹1,900 crore across 5 partners. | E21: 1900 | F21: INR crore
A22: CUS-101 | B22: Customer | C22: satisfaction | D22: Borrower CSAT is 4.1 out of 5. | E22: 4.1 | F22: score
A23: CUS-102 | B23: Customer | C23: support | D23: Average call handling time is 6.5 minutes. | E23: 6.5 | F23: minutes
A24: CUS-103 | B24: Customer | C24: support | D24: 62% of support queries are resolved by the in-app chatbot. | E24: 62 | F24: %
A25: CUS-104 | B25: Customer | C25: app | D25: App store rating is 4.3 (Android) and 4.5 (iOS). | E25: 4.3 | F25: score
A26: CUS-105 | B26: Customer | C26: onboarding | D26: Loan application drop-off at the KYC step is 18%. | E26: 18 | F26: %
A27: CUS-106 | B27: Customer | C27: communication | D27: Borrowers receive repayment reminders by SMS and WhatsApp 3 days before the due date. | E27: 3 | F27: days
A28: CUS-107 | B28: Customer | C28: support | D28: Support is available in 6 languages. | E28: 6 | F28: languages
A29: CUS-108 | B29: Customer | C29: complaints | D29: Loan-pricing complaints average 150 a month. | E29: 150 | F29: tickets / month
A30: LEG-101 | B30: Legal | C30: litigation | D30: There are 14 pending civil cases, none material. | E30: 14 | F30: cases
A31: LEG-102 | B31: Legal | C31: ip | D31: The 'Legion Pay' trademark is registered in India. | E31: registered
A32: LEG-103 | B32: Legal | C32: regulatory | D32: Legion's last RBI inspection (2025) had 3 minor observations, all closed. | E32: 3 | F32: observations
A33: LEG-104 | B33: Legal | C33: contracts | D33: The office lease in Mumbai runs until 2029. | E33: 2029
A34: LEG-105 | B34: Legal | C34: regulatory | D34: Digital lending guidelines require a key fact statement for every loan; compliance is 100%. | E34: 100 | F34: %
A35: LEG-106 | B35: Legal | C35: contracts | D35: The cloud hosting contract renews in July 2027. | E35: 2027-07
A36: LEG-107 | B36: Legal | C36: employment | D36: Standard employee notice period is 60 days. | E36: 60 | F36: days
A37: LEG-108 | B37: Legal | C37: regulatory | D37: Fair practices code was last reviewed by the board in May 2026. | E37: 2026-05
A38: SEC-101 | B38: InfoSec & Data Privacy | C38: awareness | D38: Phishing simulation click rate is 7%. | E38: 7 | F38: %
A39: SEC-102 | B39: InfoSec & Data Privacy | C39: endpoint | D39: 99% of laptops have full-disk encryption. | E39: 99 | F39: %
A40: SEC-103 | B40: InfoSec & Data Privacy | C40: certification | D40: Legion is ISO 27001 certified until March 2028. | E40: 2028-03
A41: SEC-104 | B41: InfoSec & Data Privacy | C41: access | D41: Privileged access reviews run every quarter. | E41: quarterly
A42: SEC-105 | B42: InfoSec & Data Privacy | C42: vulnerabilities | D42: Critical patching SLA is 7 days; 96% met last quarter. | E42: 96 | F42: %
...

Sheet Advisers
A1: Adviser registry
A2: Mirrors config/advisers.yaml. The harness embeds the capability statements to decide who joins each decision.
A3: ID | B3: Name | C3: Lens | D3: Capability statements (embedded for routing) | E3: Criteria scored | F3: Can block? | G3: Calculates | H3: Planted facts
A4: finance | B4: Finance | C4: Is this decision worth it in money terms, after every cost and benefit? | D4: • Costs, fees, pricing and savings • Budgets, cost-to-income ratio, return on investment and payback • Cash flow, settlement timing, funding cost and treasury • One-time investment, migration and exit costs • Revenue forecasts and unit economics • Headcount, office and infrastructure spend | E4: Cost | F4: No | G4: • Monthly cost on each option • Gross and net monthly saving • One-time costs (migration, exit fees) • Payback period in months • Effect of phasing on the numbers | H4: =COUNTIF('Planted Facts'!$B$4:$B$74,B4) -> 12
A5: business | B5: Business | C5: Does this move the company toward its strategy and growth goals? | D5: • Company strategy, OKRs and board priorities • Growth, new products, new markets and partnerships • Competitive position and market trends • Sales pipeline and new revenue opportunities • Vendor strategy and concentration risk • Time-to-market and deadlines | E5: Growth | F5: No | G5: • Revenue unlocked • Fit with each OKR • Cost of delay • Concentration after the move | H5: =COUNTIF('Planted Facts'!$B$4:$B$74,B5) -> 11
A6: customer | B6: Customer | C6: What happens to merchants and borrowers? | D6: • Merchant and borrower experience • Complaints, support tickets and grievance deadlines • Checkout conversion, refunds and payment failures customers feel • Churn, NPS, satisfaction and app reviews • Language and accessibility • Customer communication and support cost | E6: Customer impact | F6: No | G6: • Complaint trend • Revenue at risk from churn • Expected change in conversion and refunds | H6: =COUNTIF('Planted Facts'!$B$4:$B$74,B6) -> 12
A7: legal | B7: Legal | C7: Are we protected and compliant under the contracts and the law? | D7: • Contracts, terms, notice periods, exit fees and renewals • Liability, indemnity, governing law and disputes • Regulatory compliance: RBI rules, licences, outsourcing norms • Data protection law and data processing agreements • Partner, vendor and outsourcing agreements | E7: Security & compliance | F7: No | G7: • Exit fee trigger for each option • Notice deadlines • Clauses that must change before signing | H7: =COUNTIF('Planted Facts'!$B$4:$B$74,B7) -> 11
A8: infosec | B8: InfoSec & Data Privacy | C8: Is our data and our customers' data safe, and does it stay where the rules say? | D8: • Information security posture of vendors and systems • Where data is stored and processed; data localisation • Privacy, personal data sharing and the DPDP Act • Certifications: SOC 2, PCI DSS, ISO 27001 • Security incidents, breach reporting and CERT-In • Access control, encryption and tokenisation • Third-party, outsourcing and cloud vendor risk | E8: Security & compliance | F8: Yes | G8: • Risk rating per area • Blocking findings and their fixes • Pre-go-live security conditions | H8: =COUNTIF('Planted Facts'!$B$4:$B$74,B8) -> 12
A9: ops | B9: Ops & Engineering | C9: Will it work reliably, and can we deliver it? | D9: • System reliability, uptime, success rates and latency • Incidents and outages • Migration effort, engineering capacity and delivery timelines • Integrations, routing and reconciliation • Infrastructure, cloud regions and data centres • Operational processes and call-centre operations | E9: Reliability | F9: No | G9: • Success rate by bank segment • Expected success with bank-level routing • Realistic migration timeline | H9: =COUNTIF('Planted Facts'!$B$4:$B$74,B9) -> 13
G10: Total | H10: =SUM(H4:H9) -> 71

Sheet Routing Tests
A1: Routing tests for the agentic harness
A2: A test passes if every 'must include' adviser is selected and no 'must exclude' adviser is. 'Acceptable' may or may not be selected.
A3: Test | B3: Decision brief | C3: Must include | D3: Acceptable | E3: Must exclude | F3: Why
A4: RT-01 | B4: Should we move 40% of our payment volume from Arvanta Payments to Brevis Pay? | C4: Finance, Business, Customer, Legal, InfoSec & Data Privacy, Ops & Engineering | F4: Main demo decision: every adviser has something to add
A5: RT-02 | B5: Should we hire 20 more engineers for the lending platform next quarter? | C5: Finance, Business, Ops & Engineering | E5: InfoSec & Data Privacy, Customer | F5: Leaves out advisers with nothing to add
A6: RT-03 | B6: Should we share anonymised borrower repayment data with a co-lending partner? | C6: InfoSec & Data Privacy, Legal, Business | D6: Customer | E6: Ops & Engineering | F6: Data sharing must bring in InfoSec and Legal
A7: RT-04 | B7: Should we cut the personal-loan interest rate by 1 percentage point for prime borrowers? | C7: Finance, Business, Customer | D7: Legal | E7: InfoSec & Data Privacy, Ops & Engineering | F7: Pricing decision
A8: RT-05 | B8: Should we move our data warehouse to a new cloud region? | C8: InfoSec & Data Privacy, Ops & Engineering, Finance | D8: Legal | E8: Customer | F8: Infrastructure and data location
A9: RT-06 | B9: Should we launch Legion Pay Later (buy now, pay later) at checkout? | C9: Business, Finance, Customer, Legal | D9: InfoSec & Data Privacy, Ops & Engineering | F9: New product
A10: RT-07 | B10: Should we outsource customer support to a third-party call centre? | C10: Customer, Ops & Engineering, Finance, InfoSec & Data Privacy, Legal | D10: Business | F10: Outsourcing with customer data
A11: RT-08 | B11: Should we open a new office in Pune? | C11: Finance, Ops & Engineering, Business | D11: Legal | E11: InfoSec & Data Privacy, Customer | F11: Facilities decision

Sheet Moderator Tests
A1: Moderator tests
A2: Claim cases: KEEP / FLAG / STRIKE. Memo cases: PASS / INCOMPLETE / WRONG. Two control cases (MT-05, MT-14) check the moderator doesn't over-strike.
A3: Test | B3: Stage | C3: From | D3: Input | E3: Cited evidence | F3: Expected | G3: Why
A4: MT-01 | B4: claim | C4: Finance | D4: Brevis would save us 18% on fees. | E4: FIN-12 | F4: STRIKE | G4: FIN-12 is superseded by FIN-03 (final quote: 12%). Superseded facts can't support a claim.
A5: MT-02 | B5: claim | C5: Ops | D5: Migration to Brevis can be done in under 4 weeks. | E5: OPS-13 | F5: FLAG | G5: Low-reliability vendor claim that conflicts with the internal 6-week estimate (OPS-09).
A6: MT-03 | B6: claim | C6: Business | D6: Brevis has much better uptime than Arvanta. | F6: STRIKE | G6: No evidence cited. (The supporting fact OPS-04 exists but the claim must cite it.)
A7: MT-04 | B7: claim | C7: Finance | D7: Moving 40% saves ₹18 lakh a month in fees. | E7: FIN-02, FIN-03 | F7: STRIKE | G7: Cited facts give ₹120 − ₹105.6 = ₹14.4 lakh, not ₹18 lakh. Number check fails.
A8: MT-05 | B8: claim | C8: Ops | D8: Brevis's overall success rate is slightly lower than Arvanta's. | E8: OPS-01 | F8: KEEP | G8: Control case: the claim matches the evidence (97.6% vs 97.8%). The moderator must not over-strike.
A9: MT-06 | B9: claim | C9: Finance | D9: Moving 40% avoids Arvanta's exit fee. | E9: LEG-01 | F9: STRIKE | G9: Contradicts LEG-01: a 40% move leaves Arvanta at 60%, below the 80% minimum, so the ₹25 lakh fee applies.
A10: MT-07 | B10: claim | C10: InfoSec | D10: BLOCKING: card data goes to a Singapore sub-processor. | E10: SEC-01, SEC-02 | F10: KEEP | G10: Blocking finding with valid evidence. The moderator can't strike it, even if another adviser disputes it.
A11: MT-08 | B11: claim | C11: Customer | D11: Brevis improves checkout conversion by 3.1 points across all channels. | E11: CUS-04 | F11: FLAG | G11: Over-generalised: the evidence covers mobile checkout in a 2% pilot only.
A12: MT-09 | B12: memo | C12: Scribe | D12: Memo recommends moving 40% now, with no mention of the Singapore sub-processor. | E12: SEC-01 | F12: WRONG | G12: An unresolved blocking finding is ignored and not formally overridden.
A13: MT-10 | B13: memo | C13: Scribe | D13: Memo addresses cost, security, reliability and growth but says nothing about customer impact. | F13: INCOMPLETE | G13: A weighted criterion (Customer impact, 10%) is missing.
A14: MT-11 | B14: memo | C14: Scribe | D14: Memo says payback is about 3 months. | E14: FIN-03, FIN-04, FIN-05, LEG-01 | F14: WRONG | G14: Ignores the ₹40 lakh migration cost and the add-on. Correct: (₹40L + ₹25L) / ₹10.4L ≈ 6.3 months for the 40% plan.
A15: MT-12 | B15: memo | C15: Scribe | D15: Memo has no dissent section although Legal argued for waiting. | F15: INCOMPLETE | G15: Dissent from a selected adviser must be recorded.
A16: MT-13 | B16: memo | C16: Scribe | D16: Memo double-counts the exit fee as ₹50 lakh. | E16: LEG-01 | F16: WRONG | G16: The exit fee is ₹25 lakh, one-time.
A17: MT-14 | B17: memo | C17: Scribe | D17: Memo matches the expected outcome: conditional, phased move with all conditions and dissent. | F17: PASS | G17: Control case: a correct memo must pass first time.

Sheet Expected Outcome
A1: Expected outcome for the demo decision
A2: Should Legion Capital move 40% of its payment volume (about ₹600 crore a month) from Arvanta Payments to Brevis Pay?
A4: Conditional, phased move. Do not move 40% now. Phase 1: move about 15% of volume to Brevis Pay (excluding Coral Bank and Tamra Bank traffic and the eNACH banks Brevis can't serve), only after Brevis (1) contractually commits to India-only processing and switches on its India-only fraud-scoring add-on, (2) closes the open high-severity pen test finding, (3) provides a current SOC 2 Type II report, and (4) accepts contract fixes: Indian governing law, audit rights for Legion and RBI, a 24-month price lock, a signed DPA and 2-hour incident notification. Phase 1 keeps Arvanta at 85%, so no exit fee. Serve 90 days' notice to Arvanta now. Phase 2: scale to 40% after a 60-day review (target before 31 Mar 2027 to meet the 70% vendor OKR and the board's cross-border deadline), accepting the ₹25 lakh exit fee, which the net monthly benefit pays back with the migration cost in about 6 months. Dissent to record: Legal (weaker Brevis contract terms) and InfoSec (vendor maturity, slow 2025 breach disclosure) favour waiting; Business favours moving faster.
A6: Criterion | B6: Weight | C6: Scored by | D6: What good looks like
A7: Cost | B7: 0.25 | C7: Finance | D7: Lower total cost after any fixes needed
A8: Security & compliance | B8: 0.25 | C8: InfoSec & Data Privacy, Legal | D8: Meets every data, security and regulatory rule; a blocking finding overrides the score
A9: Reliability | B9: 0.2 | C9: Ops & Engineering | D9: No drop in payment success rate or uptime
A10: Growth | B10: 0.2 | C10: Business | D10: Unlocks new merchants and products; meets the vendor-concentration OKR
A11: Customer impact | B11: 0.1 | C11: Customer | D11: Fewer complaints, faster settlements and refunds, lower churn
A12: Total | B12: =SUM(B7:B11) -> 1

Sheet Tracker
A1: Colosseum tracker — Day 1 done, Days 2–11
A2: Fill in Status (dropdown) and Notes. Each day totals 120 minutes.
A3: Day | B3: Milestone | C3: Task | D3: Minutes | E3: Status | F3: Notes / next step
A4: 1 | B4: Setup done | C4: Read the competition rules and fill in the Setup tab | D4: 20 | E4: Done
A5: 1 | B5: Setup done | C5: Set up Google Cloud (project, APIs, Firestore, BigQuery, bucket) | D5: 40 | E5: Done
A6: 1 | B6: Setup done | C6: Test Gemini Flash, Pro and Embedding 001; note model IDs | D6: 30 | E6: Done
A7: 2 | B7: Data ready | C7: 2.1 Review the knowledge pack | D7: 25 | E7: Not started
A8: 2 | B8: Data ready | C8: 2.2 Load data and documents into Google Cloud | D8: 35 | E8: Not started
A9: 2 | B9: Data ready | C9: 2.3 Set up Agent Search and test 5 questions | D9: 40 | E9: Not started
A10: 2 | B10: Data ready | C10: 2.4 Project skeleton in Antigravity, committed | D10: 20 | E10: Not started
A11: 3 | B11: Tools work | C11: 3.1 Settings, registry, ledger | D11: 30 | E11: Not started
A12: 3 | B12: Tools work | C12: 3.2 Fact store, approved queries, document search | D12: 40 | E12: Not started
A13: 3 | B13: Tools work | C13: 3.3 The four adviser tools | D13: 30 | E13: Not started
A14: 3 | B14: Tools work | C14: 3.4 Unit tests and manual checks | D14: 20 | E14: Not started
A15: 4 | B15: Advisers work | C15: 4.1 Adviser factory + Finance | D15: 40 | E15: Not started
... A43: 11 | B43: Submitted | C43: 11.5 Prepare for judging and submit | D43: 15 | E43: Not started
C44: Total minutes, Days 2–11 | D44: =SUMIF(A4:A43,">1",D4:D43) -> 1200
C45: Tasks done | D45: =COUNTIF(E4:E43,"Done")&" of "&COUNTA(C4:C43) -> 3 of 40
